Workbook

Sheet UI
A1: Onderwerp: | B1: Klas | C1: Leraar | D1: Klas | E1: Keuze | F1: =33-COUNTBLANK(F3:F34) -> 9
A2: Selectie: | B2: NEV | C2: {=_xlfn.UNIQUE(Lessen!C:C)} -> BC | D2: {=_xlfn.UNIQUE(Lessen!G:G)} -> 1LATA | E2: =IF(B$1="Klas",D2,C2) -> 1LATA | F2: {=_xlfn.UNIQUE(Lessen!B1:B625)} -> /nope/
C3: BH | D3: 1LATB | E3: =IF(B$1="Klas",D3,C3) -> 1LATB | F3: 38 | I3: {=IF(Rooster!B1<>-1,INDEX(Lessen!D$1:D$625,Rooster!B1+1,1),"")} -> WIS | J3: {=IF(Rooster!B8<>-1,INDEX(Lessen!D$1:D$625,Rooster!B8+1,1),"")} -> NWET | K3: {=IF(Rooster!B15<>-1,INDEX(Lessen!D$1:D$625,Rooster!B15+1,1),"")} -> NWET | L3: {=IF(Rooster!B19<>-1,INDEX(Lessen!D$1:D$625,Rooster!B19+1,1),"")} -> NWET | M3: {=IF(Rooster!B26<>-1,INDEX(Lessen!D$1:D$625,Rooster!B26+1,1),"")}
C4: CK | D4: 1LATE | E4: =IF(B$1="Klas",D4,C4) -> 1LATE | F4: 39 | I4: {=IF(Rooster!B2<>-1,INDEX(Lessen!D$1:D$625,Rooster!B2+1,1),"")} -> WIS | J4: {=IF(Rooster!B9<>-1,INDEX(Lessen!D$1:D$625,Rooster!B9+1,1),"")} -> WIS | K4: {=IF(Rooster!B16<>-1,INDEX(Lessen!D$1:D$625,Rooster!B16+1,1),"")} | L4: {=IF(Rooster!B20<>-1,INDEX(Lessen!D$1:D$625,Rooster!B20+1,1),"")} | M4: {=IF(Rooster!B27<>-1,INDEX(Lessen!D$1:D$625,Rooster!B27+1,1),"")} -> NWET
C5: DSG | D5: 1LATC | E5: =IF(B$1="Klas",D5,C5) -> 1LATC | F5: 40 | I5: {=IF(Rooster!B3<>-1,INDEX(Lessen!D$1:D$625,Rooster!B3+1,1),"")} | J5: {=IF(Rooster!B10<>-1,INDEX(Lessen!D$1:D$625,Rooster!B10+1,1),"")} | K5: {=IF(Rooster!B17<>-1,INDEX(Lessen!D$1:D$625,Rooster!B17+1,1),"")} -> NWET | L5: {=IF(Rooster!B21<>-1,INDEX(Lessen!D$1:D$625,Rooster!B21+1,1),"")} -> NWET | M5: {=IF(Rooster!B28<>-1,INDEX(Lessen!D$1:D$625,Rooster!B28+1,1),"")}
C6: KE | D6: 1LATD | E6: =IF(B$1="Klas",D6,C6) -> 1LATD | F6: 41 | I6: {=IF(Rooster!B4<>-1,INDEX(Lessen!D$1:D$625,Rooster!B4+1,1),"")} -> WIS | J6: {=IF(Rooster!B11<>-1,INDEX(Lessen!D$1:D$625,Rooster!B11+1,1),"")} -> NWET | K6: {=IF(Rooster!B18<>-1,INDEX(Lessen!D$1:D$625,Rooster!B18+1,1),"")} | L6: {=IF(Rooster!B22<>-1,INDEX(Lessen!D$1:D$625,Rooster!B22+1,1),"")} | M6: {=IF(Rooster!B29<>-1,INDEX(Lessen!D$1:D$625,Rooster!B29+1,1),"")} -> NWET
C7: LR | E7: =IF(B$1="Klas",D7,C7) | F7: 42 | I7: {=IF(Rooster!B5<>-1,INDEX(Lessen!D$1:D$625,Rooster!B5+1,1),"")} | J7: {=IF(Rooster!B12<>-1,INDEX(Lessen!D$1:D$625,Rooster!B12+1,1),"")} | L7: {=IF(Rooster!B23<>-1,INDEX(Lessen!D$1:D$625,Rooster!B23+1,1),"")} -> NWET | M7: {=IF(Rooster!B30<>-1,INDEX(Lessen!D$1:D$625,Rooster!B30+1,1),"")}
C8: MD | D8: 2LATB | E8: =IF(B$1="Klas",D8,C8) -> 2LATB | F8: 43 | I8: {=IF(Rooster!B6<>-1,INDEX(Lessen!D$1:D$625,Rooster!B6+1,1),"")} -> NWET | J8: {=IF(Rooster!B13<>-1,INDEX(Lessen!D$1:D$625,Rooster!B13+1,1),"")} -> NWET | L8: {=IF(Rooster!B24<>-1,INDEX(Lessen!D$1:D$625,Rooster!B24+1,1),"")} | M8: {=IF(Rooster!B31<>-1,INDEX(Lessen!D$1:D$625,Rooster!B31+1,1),"")} -> WIS
C9: NEV | D9: 2LATC | E9: =IF(B$1="Klas",D9,C9) -> 2LATC | F9: 44 | I9: {=IF(Rooster!B7<>-1,INDEX(Lessen!D$1:D$625,Rooster!B7+1,1),"")} | J9: {=IF(Rooster!B14<>-1,INDEX(Lessen!D$1:D$625,Rooster!B14+1,1),"")} | L9: {=IF(Rooster!B25<>-1,INDEX(Lessen!D$1:D$625,Rooster!B25+1,1),"")} -> NWET | M9: {=IF(Rooster!B32<>-1,INDEX(Lessen!D$1:D$625,Rooster!B32+1,1),"")}
C10: PM | D10: 2LATD | E10: =IF(B$1="Klas",D10,C10) -> 2LATD | F10: 45
C11: SC | D11: 2LATE | E11: =IF(B$1="Klas",D11,C11) -> 2LATE
C12: SE | D12: 2LATA | E12: =IF(B$1="Klas",D12,C12) -> 2LATA
C13: SK | D13: 2GLAA | E13: =IF(B$1="Klas",D13,C13) -> 2GLAA
C14: SN | D14: 0 | E14: =IF(B$1="Klas",D14,C14) -> 0
C15: UK | E15: =IF(B$1="Klas",D15,C15) -> 0
C16: VBI | E16: =IF(B$1="Klas",D16,C16) -> 0
C17: VCS | E17: =IF(B$1="Klas",D17,C17) -> 0
C18: VDA | E18: =IF(B$1="Klas",D18,C18) -> 0
C19: VDMB | E19: =IF(B$1="Klas",D19,C19) -> 0
C20: VHE | E20: =IF(B$1="Klas",D20,C20) -> 0
C21: VHUE | E21: =IF(B$1="Klas",D21,C21) -> 0
C22: VM | E22: =IF(B$1="Klas",D22,C22) -> 0
C23: VMS | E23: =IF(B$1="Klas",D23,C23) -> 0
E24: =IF(B$1="Klas",D24,C24) -> 0
C25: 0 | E25: =IF(B$1="Klas",D25,C25) -> 0
E26: =IF(B$1="Klas",D26,C26) -> 0
E27: =IF(B$1="Klas",D27,C27) -> 0
E28: =IF(B$1="Klas",D28,C28) -> 0
E29: =IF(B$1="Klas",D29,C29) -> 0
E30: =IF(B$1="Klas",D30,C30) -> 0
E31: =IF(B$1="Klas",D31,C31) -> 0
E32: =IF(B$1="Klas",D32,C32) -> 0
E33: =IF(B$1="Klas",D33,C33) -> 0
E34: =IF(B$1="Klas",D34,C34) -> 0
E35: =IF(B$1="Klas",D35,C35) -> 0
E36: =IF(B$1="Klas",D36,C36) -> 0
E37: =IF(B$1="Klas",D37,C37) -> 0
... E200: =IF(B$1="Klas",D200,C200) -> 0

Sheet Rooster
A1: 97,101,71,45,113,19,21,54,117,85 | B1: {=MAX(_xlfn.MAKEARRAY(UI!F$1,1,_xlfn.LAMBDA(_xlpm.r,_xlpm.c,IF(COUNTIF(Rooster!C1:BA1,INDEX(UI!F$2:F$33,_xlpm.r,1))>0,INDEX(UI!F$2:F$33,_xlpm.r,1)+1,0))))-1} -> 45 | C1: {=IF(A1="","",_xlfn.TEXTSPLIT(A1,","))} -> 97 | D1: 101 | E1: 71 | F1: 45 | G1: 113 | H1: 19 | I1: 21 | J1: 54 | K1: 117 | L1: 85
A2: 98,100,69,74,45,114,115,85,54,22 | B2: {=MAX(_xlfn.MAKEARRAY(UI!F$1,1,_xlfn.LAMBDA(_xlpm.r,_xlpm.c,IF(COUNTIF(Rooster!C2:BA2,INDEX(UI!F$2:F$33,_xlpm.r,1))>0,INDEX(UI!F$2:F$33,_xlpm.r,1)+1,0))))-1} -> 45 | C2: {=IF(A2="","",_xlfn.TEXTSPLIT(A2,","))} -> 98 | D2: 100 | E2: 69 | F2: 74 | G2: 45 | H2: 114 | I2: 115 | J2: 85 | K2: 54 | L2: 22
A3: 96,65,64,102,113,81,23,54,87,121 | B3: {=MAX(_xlfn.MAKEARRAY(UI!F$1,1,_xlfn.LAMBDA(_xlpm.r,_xlpm.c,IF(COUNTIF(Rooster!C3:BA3,INDEX(UI!F$2:F$33,_xlpm.r,1))>0,INDEX(UI!F$2:F$33,_xlpm.r,1)+1,0))))-1} -> -1 | C3: {=IF(A3="","",_xlfn.TEXTSPLIT(A3,","))} -> 96 | D3: 65 | E3: 64 | F3: 102 | G3: 113 | H3: 81 | I3: 23 | J3: 54 | K3: 87 | L3: 121
A4: 66,98,73,45,17,114,118,55,24,88 | B4: {=MAX(_xlfn.MAKEARRAY(UI!F$1,1,_xlfn.LAMBDA(_xlpm.r,_xlpm.c,IF(COUNTIF(Rooster!C4:BA4,INDEX(UI!F$2:F$33,_xlpm.r,1))>0,INDEX(UI!F$2:F$33,_xlpm.r,1)+1,0))))-1} -> 45 | C4: {=IF(A4="","",_xlfn.TEXTSPLIT(A4,","))} -> 66 | D4: 98 | E4: 73 | F4: 45 | G4: 17 | H4: 114 | I4: 118 | J4: 55 | K4: 24 | L4: 88
A5: 89,97,67,69,76,113,20,120,25,56 | B5: {=MAX(_xlfn.MAKEARRAY(UI!F$1,1,_xlfn.LAMBDA(_xlpm.r,_xlpm.c,IF(COUNTIF(Rooster!C5:BA5,INDEX(UI!F$2:F$33,_xlpm.r,1))>0,INDEX(UI!F$2:F$33,_xlpm.r,1)+1,0))))-1} -> -1 | C5: {=IF(A5="","",_xlfn.TEXTSPLIT(A5,","))} -> 89 | D5: 97 | E5: 67 | F5: 69 | G5: 76 | H5: 113 | I5: 20 | J5: 120 | K5: 25 | L5: 56
A6: 100,68,70,38,74,18,114,21,57,122 | B6: {=MAX(_xlfn.MAKEARRAY(UI!F$1,1,_xlfn.LAMBDA(_xlpm.r,_xlpm.c,IF(COUNTIF(Rooster!C6:BA6,INDEX(UI!F$2:F$33,_xlpm.r,1))>0,INDEX(UI!F$2:F$33,_xlpm.r,1)+1,0))))-1} -> 38 | C6: {=IF(A6="","",_xlfn.TEXTSPLIT(A6,","))} -> 100 | D6: 68 | E6: 70 | F6: 38 | G6: 74 | H6: 18 | I6: 114 | J6: 21 | K6: 57 | L6: 122
A7: 97,101,72,75,82,51,22,55,89,124 | B7: {=MAX(_xlfn.MAKEARRAY(UI!F$1,1,_xlfn.LAMBDA(_xlpm.r,_xlpm.c,IF(COUNTIF(Rooster!C7:BA7,INDEX(UI!F$2:F$33,_xlpm.r,1))>0,INDEX(UI!F$2:F$33,_xlpm.r,1)+1,0))))-1} -> -1 | C7: {=IF(A7="","",_xlfn.TEXTSPLIT(A7,","))} -> 97 | D7: 101 | E7: 72 | F7: 75 | G7: 82 | H7: 51 | I7: 22 | J7: 55 | K7: 89 | L7: 124
A8: 64,66,102,42,77,17,52,23,56,95 | B8: {=MAX(_xlfn.MAKEARRAY(UI!F$1,1,_xlfn.LAMBDA(_xlpm.r,_xlpm.c,IF(COUNTIF(Rooster!C8:BA8,INDEX(UI!F$2:F$33,_xlpm.r,1))>0,INDEX(UI!F$2:F$33,_xlpm.r,1)+1,0))))-1} -> 42 | C8: {=IF(A8="","",_xlfn.TEXTSPLIT(A8,","))} -> 64 | D8: 66 | E8: 102 | F8: 42 | G8: 77 | H8: 17 | I8: 52 | J8: 23 | K8: 56 | L8: 95
A9: 67,73,45,113,19,86,120,57,58,24 | B9: {=MAX(_xlfn.MAKEARRAY(UI!F$1,1,_xlfn.LAMBDA(_xlpm.r,_xlpm.c,IF(COUNTIF(Rooster!C9:BA9,INDEX(UI!F$2:F$33,_xlpm.r,1))>0,INDEX(UI!F$2:F$33,_xlpm.r,1)+1,0))))-1} -> 45 | C9: {=IF(A9="","",_xlfn.TEXTSPLIT(A9,","))} -> 67 | D9: 73 | E9: 45 | F9: 113 | G9: 19 | H9: 86 | I9: 120 | J9: 57 | K9: 58 | L9: 24
A10: 98,70,114,84,20,87,55,25,123,125 | B10: {=MAX(_xlfn.MAKEARRAY(UI!F$1,1,_xlfn.LAMBDA(_xlpm.r,_xlpm.c,IF(COUNTIF(Rooster!C10:BA10,INDEX(UI!F$2:F$33,_xlpm.r,1))>0,INDEX(UI!F$2:F$33,_xlpm.r,1)+1,0))))-1} -> -1 | C10: {=IF(A10="","",_xlfn.TEXTSPLIT(A10,","))} -> 98 | D10: 70 | E10: 114 | F10: 84 | G10: 20 | H10: 87 | I10: 55 | J10: 25 | K10: 123 | L10: 125
A11: 65,101,39,71,75,15,50,88,56,61 | B11: {=MAX(_xlfn.MAKEARRAY(UI!F$1,1,_xlfn.LAMBDA(_xlpm.r,_xlpm.c,IF(COUNTIF(Rooster!C11:BA11,INDEX(UI!F$2:F$33,_xlpm.r,1))>0,INDEX(UI!F$2:F$33,_xlpm.r,1)+1,0))))-1} -> 39 | C11: {=IF(A11="","",_xlfn.TEXTSPLIT(A11,","))} -> 65 | D11: 101 | E11: 39 | F11: 71 | G11: 75 | H11: 15 | I11: 50 | J11: 88 | K11: 56 | L11: 61
A12: 3,68,105,14,83,51,121,90,62,95 | B12: {=MAX(_xlfn.MAKEARRAY(UI!F$1,1,_xlfn.LAMBDA(_xlpm.r,_xlpm.c,IF(COUNTIF(Rooster!C12:BA12,INDEX(UI!F$2:F$33,_xlpm.r,1))>0,INDEX(UI!F$2:F$33,_xlpm.r,1)+1,0))))-1} -> -1 | C12: {=IF(A12="","",_xlfn.TEXTSPLIT(A12,","))} -> 3 | D12: 68 | E12: 105 | F12: 14 | G12: 83 | H12: 51 | I12: 121 | J12: 90 | K12: 62 | L12: 95
... A32: 66,101,74,50,114,115,88,57,61,31 | B32: {=MAX(_xlfn.MAKEARRAY(UI!F$1,1,_xlfn.LAMBDA(_xlpm.r,_xlpm.c,IF(COUNTIF(Rooster!C32:BA32,INDEX(UI!F$2:F$33,_xlpm.r,1))>0,INDEX(UI!F$2:F$33,_xlpm.r,1)+1,0))))-1} -> -1 | C32: {=IF(A32="","",_xlfn.TEXTSPLIT(A32,","))} -> 66 | D32: 101 | E32: 74 | F32: 50 | G32: 114 | H32: 115 | I32: 88 | J32: 57 | K32: 61 | L32: 31

Sheet Lessen
A1: BC,GODSD,1LATA,2 | B1: =IF(COUNTIF(C1:I1,UI!B$2)=0,"/nope/",ROW(A1)-1) -> /nope/ | C1: {=IF(A1="","",_xlfn.TEXTSPLIT(A1,","))} -> BC | D1: GODSD | E1: 1LATA | F1: 2 | G1: =IF(E1="","",IF(I1="",E1,"")) -> 1LATA | H1: {=_xlfn.TEXTSPLIT(E1,"/")} -> 1LATA
A2: BC,GODSD,1LATB,2 | B2: =IF(COUNTIF(C2:I2,UI!B$2)=0,"/nope/",ROW(A2)-1) -> /nope/ | C2: {=IF(A2="","",_xlfn.TEXTSPLIT(A2,","))} -> BC | D2: GODSD | E2: 1LATB | F2: 2 | G2: =IF(E2="","",IF(I2="",E2,"")) -> 1LATB | H2: {=_xlfn.TEXTSPLIT(E2,"/")} -> 1LATB
A3: BC,GODSD,1LATE,2 | B3: =IF(COUNTIF(C3:I3,UI!B$2)=0,"/nope/",ROW(A3)-1) -> /nope/ | C3: {=IF(A3="","",_xlfn.TEXTSPLIT(A3,","))} -> BC | D3: GODSD | E3: 1LATE | F3: 2 | G3: =IF(E3="","",IF(I3="",E3,"")) -> 1LATE | H3: {=_xlfn.TEXTSPLIT(E3,"/")} -> 1LATE
A4: BC,GODSD,1LATC,2 | B4: =IF(COUNTIF(C4:I4,UI!B$2)=0,"/nope/",ROW(A4)-1) -> /nope/ | C4: {=IF(A4="","",_xlfn.TEXTSPLIT(A4,","))} -> BC | D4: GODSD | E4: 1LATC | F4: 2 | G4: =IF(E4="","",IF(I4="",E4,"")) -> 1LATC | H4: {=_xlfn.TEXTSPLIT(E4,"/")} -> 1LATC
A5: BC,GODSD,1LATD,2 | B5: =IF(COUNTIF(C5:I5,UI!B$2)=0,"/nope/",ROW(A5)-1) -> /nope/ | C5: {=IF(A5="","",_xlfn.TEXTSPLIT(A5,","))} -> BC | D5: GODSD | E5: 1LATD | F5: 2 | G5: =IF(E5="","",IF(I5="",E5,"")) -> 1LATD | H5: {=_xlfn.TEXTSPLIT(E5,"/")} -> 1LATD
A6: BH,LO,2GLAA/2LATA,1 | B6: =IF(COUNTIF(C6:I6,UI!B$2)=0,"/nope/",ROW(A6)-1) -> /nope/ | C6: {=IF(A6="","",_xlfn.TEXTSPLIT(A6,","))} -> BH | D6: LO | E6: 2GLAA/2LATA | F6: 1 | G6: =IF(E6="","",IF(I6="",E6,"")) | H6: {=_xlfn.TEXTSPLIT(E6,"/")} -> 2GLAA | I6: 2LATA
A7: BH,LO,2LATB,2 | B7: =IF(COUNTIF(C7:I7,UI!B$2)=0,"/nope/",ROW(A7)-1) -> /nope/ | C7: {=IF(A7="","",_xlfn.TEXTSPLIT(A7,","))} -> BH | D7: LO | E7: 2LATB | F7: 2 | G7: =IF(E7="","",IF(I7="",E7,"")) -> 2LATB | H7: {=_xlfn.TEXTSPLIT(E7,"/")} -> 2LATB
A8: BH,LO,2LATC,2 | B8: =IF(COUNTIF(C8:I8,UI!B$2)=0,"/nope/",ROW(A8)-1) -> /nope/ | C8: {=IF(A8="","",_xlfn.TEXTSPLIT(A8,","))} -> BH | D8: LO | E8: 2LATC | F8: 2 | G8: =IF(E8="","",IF(I8="",E8,"")) -> 2LATC | H8: {=_xlfn.TEXTSPLIT(E8,"/")} -> 2LATC
A9: BH,LO,2LATD,2 | B9: =IF(COUNTIF(C9:I9,UI!B$2)=0,"/nope/",ROW(A9)-1) -> /nope/ | C9: {=IF(A9="","",_xlfn.TEXTSPLIT(A9,","))} -> BH | D9: LO | E9: 2LATD | F9: 2 | G9: =IF(E9="","",IF(I9="",E9,"")) -> 2LATD | H9: {=_xlfn.TEXTSPLIT(E9,"/")} -> 2LATD
A10: BH,LO,2LATE,2 | B10: =IF(COUNTIF(C10:I10,UI!B$2)=0,"/nope/",ROW(A10)-1) -> /nope/ | C10: {=IF(A10="","",_xlfn.TEXTSPLIT(A10,","))} -> BH | D10: LO | E10: 2LATE | F10: 2 | G10: =IF(E10="","",IF(I10="",E10,"")) -> 2LATE | H10: {=_xlfn.TEXTSPLIT(E10,"/")} -> 2LATE
A11: CK,LO,1LATA,2 | B11: =IF(COUNTIF(C11:I11,UI!B$2)=0,"/nope/",ROW(A11)-1) -> /nope/ | C11: {=IF(A11="","",_xlfn.TEXTSPLIT(A11,","))} -> CK | D11: LO | E11: 1LATA | F11: 2 | G11: =IF(E11="","",IF(I11="",E11,"")) -> 1LATA | H11: {=_xlfn.TEXTSPLIT(E11,"/")} -> 1LATA
A12: CK,LO,1LATB,2 | B12: =IF(COUNTIF(C12:I12,UI!B$2)=0,"/nope/",ROW(A12)-1) -> /nope/ | C12: {=IF(A12="","",_xlfn.TEXTSPLIT(A12,","))} -> CK | D12: LO | E12: 1LATB | F12: 2 | G12: =IF(E12="","",IF(I12="",E12,"")) -> 1LATB | H12: {=_xlfn.TEXTSPLIT(E12,"/")} -> 1LATB
A13: CK,LO,1LATE,2 | B13: =IF(COUNTIF(C13:I13,UI!B$2)=0,"/nope/",ROW(A13)-1) -> /nope/ | C13: {=IF(A13="","",_xlfn.TEXTSPLIT(A13,","))} -> CK | D13: LO | E13: 1LATE | F13: 2 | G13: =IF(E13="","",IF(I13="",E13,"")) -> 1LATE | H13: {=_xlfn.TEXTSPLIT(E13,"/")} -> 1LATE
A14: CK,LO,1LATC,2 | B14: =IF(COUNTIF(C14:I14,UI!B$2)=0,"/nope/",ROW(A14)-1) -> /nope/ | C14: {=IF(A14="","",_xlfn.TEXTSPLIT(A14,","))} -> CK | D14: LO | E14: 1LATC | F14: 2 | G14: =IF(E14="","",IF(I14="",E14,"")) -> 1LATC | H14: {=_xlfn.TEXTSPLIT(E14,"/")} -> 1LATC
A15: CK,LO,1LATD,2 | B15: =IF(COUNTIF(C15:I15,UI!B$2)=0,"/nope/",ROW(A15)-1) -> /nope/ | C15: {=IF(A15="","",_xlfn.TEXTSPLIT(A15,","))} -> CK | D15: LO | E15: 1LATD | F15: 2 | G15: =IF(E15="","",IF(I15="",E15,"")) -> 1LATD | H15: {=_xlfn.TEXTSPLIT(E15,"/")} -> 1LATD
A16: CK,LO,2GLAA/2LATA,1 | B16: =IF(COUNTIF(C16:I16,UI!B$2)=0,"/nope/",ROW(A16)-1) -> /nope/ | C16: {=IF(A16="","",_xlfn.TEXTSPLIT(A16,","))} -> CK | D16: LO | E16: 2GLAA/2LATA | F16: 1 | G16: =IF(E16="","",IF(I16="",E16,"")) | H16: {=_xlfn.TEXTSPLIT(E16,"/")} -> 2GLAA | I16: 2LATA
A17: DSG,NED,2GLAA/2LATA,1 | B17: =IF(COUNTIF(C17:I17,UI!B$2)=0,"/nope/",ROW(A17)-1) -> /nope/ | C17: {=IF(A17="","",_xlfn.TEXTSPLIT(A17,","))} -> DSG | D17: NED | E17: 2GLAA/2LATA | F17: 1 | G17: =IF(E17="","",IF(I17="",E17,"")) | H17: {=_xlfn.TEXTSPLIT(E17,"/")} -> 2GLAA | I17: 2LATA
A18: DSG,NED,2LATD,4 | B18: =IF(COUNTIF(C18:I18,UI!B$2)=0,"/nope/",ROW(A18)-1) -> /nope/ | C18: {=IF(A18="","",_xlfn.TEXTSPLIT(A18,","))} -> DSG | D18: NED | E18: 2LATD | F18: 4 | G18: =IF(E18="","",IF(I18="",E18,"")) -> 2LATD | H18: {=_xlfn.TEXTSPLIT(E18,"/")} -> 2LATD
A19: DSG,NED,2GLAA/2LATA,3 | B19: =IF(COUNTIF(C19:I19,UI!B$2)=0,"/nope/",ROW(A19)-1) -> /nope/ | C19: {=IF(A19="","",_xlfn.TEXTSPLIT(A19,","))} -> DSG | D19: NED | E19: 2GLAA/2LATA | F19: 3 | G19: =IF(E19="","",IF(I19="",E19,"")) | H19: {=_xlfn.TEXTSPLIT(E19,"/")} -> 2GLAA | I19: 2LATA
A20: DSG,NED,2LATB,4 | B20: =IF(COUNTIF(C20:I20,UI!B$2)=0,"/nope/",ROW(A20)-1) -> /nope/ | C20: {=IF(A20="","",_xlfn.TEXTSPLIT(A20,","))} -> DSG | D20: NED | E20: 2LATB | F20: 4 | G20: =IF(E20="","",IF(I20="",E20,"")) -> 2LATB | H20: {=_xlfn.TEXTSPLIT(E20,"/")} -> 2LATB
A21: DSG,NED,2LATE,4 | B21: =IF(COUNTIF(C21:I21,UI!B$2)=0,"/nope/",ROW(A21)-1) -> /nope/ | C21: {=IF(A21="","",_xlfn.TEXTSPLIT(A21,","))} -> DSG | D21: NED | E21: 2LATE | F21: 4 | G21: =IF(E21="","",IF(I21="",E21,"")) -> 2LATE | H21: {=_xlfn.TEXTSPLIT(E21,"/")} -> 2LATE
A22: KE,NED,1LATA,4 | B22: =IF(COUNTIF(C22:I22,UI!B$2)=0,"/nope/",ROW(A22)-1) -> /nope/ | C22: {=IF(A22="","",_xlfn.TEXTSPLIT(A22,","))} -> KE | D22: NED | E22: 1LATA | F22: 4 | G22: =IF(E22="","",IF(I22="",E22,"")) -> 1LATA | H22: {=_xlfn.TEXTSPLIT(E22,"/")} -> 1LATA
A23: KE,NED,1LATB,4 | B23: =IF(COUNTIF(C23:I23,UI!B$2)=0,"/nope/",ROW(A23)-1) -> /nope/ | C23: {=IF(A23="","",_xlfn.TEXTSPLIT(A23,","))} -> KE | D23: NED | E23: 1LATB | F23: 4 | G23: =IF(E23="","",IF(I23="",E23,"")) -> 1LATB | H23: {=_xlfn.TEXTSPLIT(E23,"/")} -> 1LATB
A24: KE,NED,1LATE,4 | B24: =IF(COUNTIF(C24:I24,UI!B$2)=0,"/nope/",ROW(A24)-1) -> /nope/ | C24: {=IF(A24="","",_xlfn.TEXTSPLIT(A24,","))} -> KE | D24: NED | E24: 1LATE | F24: 4 | G24: =IF(E24="","",IF(I24="",E24,"")) -> 1LATE | H24: {=_xlfn.TEXTSPLIT(E24,"/")} -> 1LATE
A25: KE,NED,1LATC,4 | B25: =IF(COUNTIF(C25:I25,UI!B$2)=0,"/nope/",ROW(A25)-1) -> /nope/ | C25: {=IF(A25="","",_xlfn.TEXTSPLIT(A25,","))} -> KE | D25: NED | E25: 1LATC | F25: 4 | G25: =IF(E25="","",IF(I25="",E25,"")) -> 1LATC | H25: {=_xlfn.TEXTSPLIT(E25,"/")} -> 1LATC
A26: KE,NED,1LATD,4 | B26: =IF(COUNTIF(C26:I26,UI!B$2)=0,"/nope/",ROW(A26)-1) -> /nope/ | C26: {=IF(A26="","",_xlfn.TEXTSPLIT(A26,","))} -> KE | D26: NED | E26: 1LATD | F26: 4 | G26: =IF(E26="","",IF(I26="",E26,"")) -> 1LATD | H26: {=_xlfn.TEXTSPLIT(E26,"/")} -> 1LATD
A27: LR,AARDR,2LATB,1 | B27: =IF(COUNTIF(C27:I27,UI!B$2)=0,"/nope/",ROW(A27)-1) -> /nope/ | C27: {=IF(A27="","",_xlfn.TEXTSPLIT(A27,","))} -> LR | D27: AARDR | E27: 2LATB | F27: 1 | G27: =IF(E27="","",IF(I27="",E27,"")) -> 2LATB | H27: {=_xlfn.TEXTSPLIT(E27,"/")} -> 2LATB
A28: LR,AARDR,2GLAA/2LATA,1 | B28: =IF(COUNTIF(C28:I28,UI!B$2)=0,"/nope/",ROW(A28)-1) -> /nope/ | C28: {=IF(A28="","",_xlfn.TEXTSPLIT(A28,","))} -> LR | D28: AARDR | E28: 2GLAA/2LATA | F28: 1 | G28: =IF(E28="","",IF(I28="",E28,"")) | H28: {=_xlfn.TEXTSPLIT(E28,"/")} -> 2GLAA | I28: 2LATA
A29: LR,AARDR,1LATE,2 | B29: =IF(COUNTIF(C29:I29,UI!B$2)=0,"/nope/",ROW(A29)-1) -> /nope/ | C29: {=IF(A29="","",_xlfn.TEXTSPLIT(A29,","))} -> LR | D29: AARDR | E29: 1LATE | F29: 2 | G29: =IF(E29="","",IF(I29="",E29,"")) -> 1LATE | H29: {=_xlfn.TEXTSPLIT(E29,"/")} -> 1LATE
A30: LR,AARDR,1LATD,2 | B30: =IF(COUNTIF(C30:I30,UI!B$2)=0,"/nope/",ROW(A30)-1) -> /nope/ | C30: {=IF(A30="","",_xlfn.TEXTSPLIT(A30,","))} -> LR | D30: AARDR | E30: 1LATD | F30: 2 | G30: =IF(E30="","",IF(I30="",E30,"")) -> 1LATD | H30: {=_xlfn.TEXTSPLIT(E30,"/")} -> 1LATD
A31: LR,NWET,2LATC,1 | B31: =IF(COUNTIF(C31:I31,UI!B$2)=0,"/nope/",ROW(A31)-1) -> /nope/ | C31: {=IF(A31="","",_xlfn.TEXTSPLIT(A31,","))} -> LR | D31: NWET | E31: 2LATC | F31: 1 | G31: =IF(E31="","",IF(I31="",E31,"")) -> 2LATC | H31: {=_xlfn.TEXTSPLIT(E31,"/")} -> 2LATC
A32: LR,NWET,2LATD,1 | B32: =IF(COUNTIF(C32:I32,UI!B$2)=0,"/nope/",ROW(A32)-1) -> /nope/ | C32: {=IF(A32="","",_xlfn.TEXTSPLIT(A32,","))} -> LR | D32: NWET | E32: 2LATD | F32: 1 | G32: =IF(E32="","",IF(I32="",E32,"")) -> 2LATD | H32: {=_xlfn.TEXTSPLIT(E32,"/")} -> 2LATD
A33: LR,NWET,2LATE,1 | B33: =IF(COUNTIF(C33:I33,UI!B$2)=0,"/nope/",ROW(A33)-1) -> /nope/ | C33: {=IF(A33="","",_xlfn.TEXTSPLIT(A33,","))} -> LR | D33: NWET | E33: 2LATE | F33: 1 | G33: =IF(E33="","",IF(I33="",E33,"")) -> 2LATE | H33: {=_xlfn.TEXTSPLIT(E33,"/")} -> 2LATE
A34: MD,AV,2LATA,2 | B34: =IF(COUNTIF(C34:I34,UI!B$2)=0,"/nope/",ROW(A34)-1) -> /nope/ | C34: {=IF(A34="","",_xlfn.TEXTSPLIT(A34,","))} -> MD | D34: AV | E34: 2LATA | F34: 2 | G34: =IF(E34="","",IF(I34="",E34,"")) -> 2LATA | H34: {=_xlfn.TEXTSPLIT(E34,"/")} -> 2LATA
A35: MD,AV,2LATB,2 | B35: =IF(COUNTIF(C35:I35,UI!B$2)=0,"/nope/",ROW(A35)-1) -> /nope/ | C35: {=IF(A35="","",_xlfn.TEXTSPLIT(A35,","))} -> MD | D35: AV | E35: 2LATB | F35: 2 | G35: =IF(E35="","",IF(I35="",E35,"")) -> 2LATB | H35: {=_xlfn.TEXTSPLIT(E35,"/")} -> 2LATB
A36: MD,AV,2LATC,2 | B36: =IF(COUNTIF(C36:I36,UI!B$2)=0,"/nope/",ROW(A36)-1) -> /nope/ | C36: {=IF(A36="","",_xlfn.TEXTSPLIT(A36,","))} -> MD | D36: AV | E36: 2LATC | F36: 2 | G36: =IF(E36="","",IF(I36="",E36,"")) -> 2LATC | H36: {=_xlfn.TEXTSPLIT(E36,"/")} -> 2LATC
A37: MD,AV,2LATD,2 | B37: =IF(COUNTIF(C37:I37,UI!B$2)=0,"/nope/",ROW(A37)-1) -> /nope/ | C37: {=IF(A37="","",_xlfn.TEXTSPLIT(A37,","))} -> MD | D37: AV | E37: 2LATD | F37: 2 | G37: =IF(E37="","",IF(I37="",E37,"")) -> 2LATD | H37: {=_xlfn.TEXTSPLIT(E37,"/")} -> 2LATD
A38: MD,AV,2LATE,2 | B38: =IF(COUNTIF(C38:I38,UI!B$2)=0,"/nope/",ROW(A38)-1) -> /nope/ | C38: {=IF(A38="","",_xlfn.TEXTSPLIT(A38,","))} -> MD | D38: AV | E38: 2LATE | F38: 2 | G38: =IF(E38="","",IF(I38="",E38,"")) -> 2LATE | H38: {=_xlfn.TEXTSPLIT(E38,"/")} -> 2LATE
A39: NEV,NWET,2LATB,1 | B39: =IF(COUNTIF(C39:I39,UI!B$2)=0,"/nope/",ROW(A39)-1) -> 38 | C39: {=IF(A39="","",_xlfn.TEXTSPLIT(A39,","))} -> NEV | D39: NWET | E39: 2LATB | F39: 1 | G39: =IF(E39="","",IF(I39="",E39,"")) -> 2LATB | H39: {=_xlfn.TEXTSPLIT(E39,"/")} -> 2LATB
A40: NEV,NWET,1LATA,2 | B40: =IF(COUNTIF(C40:I40,UI!B$2)=0,"/nope/",ROW(A40)-1) -> 39 | C40: {=IF(A40="","",_xlfn.TEXTSPLIT(A40,","))} -> NEV | D40: NWET | E40: 1LATA | F40: 2 | G40: =IF(E40="","",IF(I40="",E40,"")) -> 1LATA | H40: {=_xlfn.TEXTSPLIT(E40,"/")} -> 1LATA
...
